from context.shared.domain.exception.internal.internal_base_error import InternalBaseError


class UnexpectedError(InternalBaseError):
    pass
